Workbook

Sheet Listas
A1: Ambiente | B1: Origem do Defeito | C1: Fase de Introdução | D1: Fase de Detecção | E1: Tipo do Defeito | F1: Severidade | G1: Prioridade | H1: Impacto no Negócio | I1: Status | J1: Necessitou Retrabalho?
A2: Desenvolvimento | B2: Requisito | C2: Requisitos | D2: Requisitos | E2: Funcional | F2: Crítica | G2: Alta | H2: Alto | I2: Aberto | J2: Sim
A3: Homologação | B3: Design | C3: Design | D3: Design | E3: Interface | F3: Alta | G3: Média | H3: Médio | I3: Em Análise | J3: Não
A4: Produção | B4: Codificação | C4: Codificação | D4: Codificação | E4: Desempenho | F4: Média | G4: Baixa | H4: Baixo | I4: Em Correção
B5: Integração | C5: Integração | D5: Integração | E5: Segurança | F5: Baixa | I5: Em Reteste
B6: Teste | C6: Teste | D6: Teste | E6: Usabilidade | I6: Fechado
B7: Implantação | C7: Implantação | D7: Implantação | E7: Compatibilidade | I7: Cancelado
C8: Produção | D8: Produção | E8: Documentação
E9: Dados
E10: Infraestrutura
E11: Outro

Sheet Defeitos
A1: ID do Defeito | B1: Data de Identificação | C1: Projeto | D1: Versão | E1: Sprint / Iteração | F1: Módulo / Componente | G1: Requisito Relacionado | H1: Ambiente | I1: Origem do Defeito | J1: Fase de Introdução do Defeito | K1: Fase de Detecção do Defeito | L1: Tipo do Defeito | M1: Descrição Resumida | N1: Severidade | O1: Prioridade | P1: Impacto no Negócio | Q1: Responsável pela Correção | R1: Data de Correção | S1: Status | T1: Tempo para Correção (dias) | U1: Necessitou Retrabalho? | V1: Causa Raiz | W1: Ação Corretiva | X1: Ação Preventiva | Y1: Lição Aprendida | Z1: Observações | AA1: Tempo Gasto na Correção (min) | AB1: Fase em que Deveria Ter Sido Removido | AC1: Linhas Alteradas na Correção (LOC)
T2: =IF(AND(B2<>"",R2<>""),R2-B2,"")
T3: =IF(AND(B3<>"",R3<>""),R3-B3,"")
T4: =IF(AND(B4<>"",R4<>""),R4-B4,"")
T5: =IF(AND(B5<>"",R5<>""),R5-B5,"")
T6: =IF(AND(B6<>"",R6<>""),R6-B6,"")
T7: =IF(AND(B7<>"",R7<>""),R7-B7,"")
T8: =IF(AND(B8<>"",R8<>""),R8-B8,"")
T9: =IF(AND(B9<>"",R9<>""),R9-B9,"")
T10: =IF(AND(B10<>"",R10<>""),R10-B10,"")
T11: =IF(AND(B11<>"",R11<>""),R11-B11,"")
T12: =IF(AND(B12<>"",R12<>""),R12-B12,"")
T13: =IF(AND(B13<>"",R13<>""),R13-B13,"")
... T500: =IF(AND(B500<>"",R500<>""),R500-B500,"")

Sheet Dashboards
A1: Painel de Defeitos
A3: Total de Defeitos | B3: =COUNTA(Defeitos!A2:A500)
A5: Defeitos por Severidade | D5: Tendência Mensal (Identificados)
A6: Categoria | B6: Quantidade | D6: Mês | E6: Quantidade
A7: Crítica | B7: =COUNTIF(Defeitos!$N$2:$N$500,$A7) | D7: 2026-01 | E7: =COUNTIFS(Defeitos!$B$2:$B$500,">="&DATE(2026,1,1),Defeitos!$B$2:$B$500,"<="&DATE(2026,1,DAY(EOMONTH(DATE(2026,1,1),0))))
A8: Alta | B8: =COUNTIF(Defeitos!$N$2:$N$500,$A8) | D8: 2026-02 | E8: =COUNTIFS(Defeitos!$B$2:$B$500,">="&DATE(2026,2,1),Defeitos!$B$2:$B$500,"<="&DATE(2026,2,DAY(EOMONTH(DATE(2026,2,1),0))))
A9: Média | B9: =COUNTIF(Defeitos!$N$2:$N$500,$A9) | D9: 2026-03 | E9: =COUNTIFS(Defeitos!$B$2:$B$500,">="&DATE(2026,3,1),Defeitos!$B$2:$B$500,"<="&DATE(2026,3,DAY(EOMONTH(DATE(2026,3,1),0))))
A10: Baixa | B10: =COUNTIF(Defeitos!$N$2:$N$500,$A10) | D10: 2026-04 | E10: =COUNTIFS(Defeitos!$B$2:$B$500,">="&DATE(2026,4,1),Defeitos!$B$2:$B$500,"<="&DATE(2026,4,DAY(EOMONTH(DATE(2026,4,1),0))))
D11: 2026-05 | E11: =COUNTIFS(Defeitos!$B$2:$B$500,">="&DATE(2026,5,1),Defeitos!$B$2:$B$500,"<="&DATE(2026,5,DAY(EOMONTH(DATE(2026,5,1),0))))
D12: 2026-06 | E12: =COUNTIFS(Defeitos!$B$2:$B$500,">="&DATE(2026,6,1),Defeitos!$B$2:$B$500,"<="&DATE(2026,6,DAY(EOMONTH(DATE(2026,6,1),0))))
A13: Defeitos por Tipo | D13: 2026-07 | E13: =COUNTIFS(Defeitos!$B$2:$B$500,">="&DATE(2026,7,1),Defeitos!$B$2:$B$500,"<="&DATE(2026,7,DAY(EOMONTH(DATE(2026,7,1),0))))
A14: Categoria | B14: Quantidade | D14: 2026-08 | E14: =COUNTIFS(Defeitos!$B$2:$B$500,">="&DATE(2026,8,1),Defeitos!$B$2:$B$500,"<="&DATE(2026,8,DAY(EOMONTH(DATE(2026,8,1),0))))
A15: Funcional | B15: =COUNTIF(Defeitos!$L$2:$L$500,$A15) | D15: 2026-09 | E15: =COUNTIFS(Defeitos!$B$2:$B$500,">="&DATE(2026,9,1),Defeitos!$B$2:$B$500,"<="&DATE(2026,9,DAY(EOMONTH(DATE(2026,9,1),0))))
A16: Interface | B16: =COUNTIF(Defeitos!$L$2:$L$500,$A16) | D16: 2026-10 | E16: =COUNTIFS(Defeitos!$B$2:$B$500,">="&DATE(2026,10,1),Defeitos!$B$2:$B$500,"<="&DATE(2026,10,DAY(EOMONTH(DATE(2026,10,1),0))))
A17: Desempenho | B17: =COUNTIF(Defeitos!$L$2:$L$500,$A17) | D17: 2026-11 | E17: =COUNTIFS(Defeitos!$B$2:$B$500,">="&DATE(2026,11,1),Defeitos!$B$2:$B$500,"<="&DATE(2026,11,DAY(EOMONTH(DATE(2026,11,1),0))))
A18: Segurança | B18: =COUNTIF(Defeitos!$L$2:$L$500,$A18) | D18: 2026-12 | E18: =COUNTIFS(Defeitos!$B$2:$B$500,">="&DATE(2026,12,1),Defeitos!$B$2:$B$500,"<="&DATE(2026,12,DAY(EOMONTH(DATE(2026,12,1),0))))
A19: Usabilidade | B19: =COUNTIF(Defeitos!$L$2:$L$500,$A19)
A20: Compatibilidade | B20: =COUNTIF(Defeitos!$L$2:$L$500,$A20)
A21: Documentação | B21: =COUNTIF(Defeitos!$L$2:$L$500,$A21) | D21: Defeitos por Módulo
A22: Dados | B22: =COUNTIF(Defeitos!$L$2:$L$500,$A22) | D22: Módulo / Componente | E22: Quantidade
A23: Infraestrutura | B23: =COUNTIF(Defeitos!$L$2:$L$500,$A23) | E23: =IF($D23="","",COUNTIF(Defeitos!$F$2:$F$500,$D23))
A24: Outro | B24: =COUNTIF(Defeitos!$L$2:$L$500,$A24) | E24: =IF($D24="","",COUNTIF(Defeitos!$F$2:$F$500,$D24))
E25: =IF($D25="","",COUNTIF(Defeitos!$F$2:$F$500,$D25))
E26: =IF($D26="","",COUNTIF(Defeitos!$F$2:$F$500,$D26))
A27: Defeitos por Fase de Introdução | E27: =IF($D27="","",COUNTIF(Defeitos!$F$2:$F$500,$D27))
A28: Categoria | B28: Quantidade | E28: =IF($D28="","",COUNTIF(Defeitos!$F$2:$F$500,$D28))
A29: Requisitos | B29: =COUNTIF(Defeitos!$J$2:$J$500,$A29) | E29: =IF($D29="","",COUNTIF(Defeitos!$F$2:$F$500,$D29))
A30: Design | B30: =COUNTIF(Defeitos!$J$2:$J$500,$A30) | E30: =IF($D30="","",COUNTIF(Defeitos!$F$2:$F$500,$D30))
A31: Codificação | B31: =COUNTIF(Defeitos!$J$2:$J$500,$A31) | E31: =IF($D31="","",COUNTIF(Defeitos!$F$2:$F$500,$D31))
A32: Integração | B32: =COUNTIF(Defeitos!$J$2:$J$500,$A32) | E32: =IF($D32="","",COUNTIF(Defeitos!$F$2:$F$500,$D32))
A33: Teste | B33: =COUNTIF(Defeitos!$J$2:$J$500,$A33)
A34: Implantação | B34: =COUNTIF(Defeitos!$J$2:$J$500,$A34)
A35: Produção | B35: =COUNTIF(Defeitos!$J$2:$J$500,$A35)
A38: Defeitos por Status
A39: Categoria | B39: Quantidade
A40: Aberto | B40: =COUNTIF(Defeitos!$S$2:$S$500,$A40)
A41: Em Análise | B41: =COUNTIF(Defeitos!$S$2:$S$500,$A41)
A42: Em Correção | B42: =COUNTIF(Defeitos!$S$2:$S$500,$A42)
A43: Em Reteste | B43: =COUNTIF(Defeitos!$S$2:$S$500,$A43)
A44: Fechado | B44: =COUNTIF(Defeitos!$S$2:$S$500,$A44)
...
